[2022-11-18T08:43:36.835+0000] {taskinstance.py:1165} INFO - Dependencies all met for <TaskInstance: DevDataOps.export_annotation manual__2022-11-18T08:43:32.597221+00:00 [queued]>
[2022-11-18T08:43:36.914+0000] {taskinstance.py:1165} INFO - Dependencies all met for <TaskInstance: DevDataOps.export_annotation manual__2022-11-18T08:43:32.597221+00:00 [queued]>
[2022-11-18T08:43:36.916+0000] {taskinstance.py:1362} INFO - 
--------------------------------------------------------------------------------
[2022-11-18T08:43:36.917+0000] {taskinstance.py:1363} INFO - Starting attempt 1 of 1
[2022-11-18T08:43:36.926+0000] {taskinstance.py:1364} INFO - 
--------------------------------------------------------------------------------
[2022-11-18T08:43:36.986+0000] {taskinstance.py:1383} INFO - Executing <Task(BashOperator): export_annotation> on 2022-11-18 08:43:32.597221+00:00
[2022-11-18T08:43:37.012+0000] {standard_task_runner.py:55} INFO - Started process 2329 to run task
[2022-11-18T08:43:37.048+0000] {standard_task_runner.py:82} INFO - Running: ['***', 'tasks', 'run', 'DevDataOps', 'export_annotation', 'manual__2022-11-18T08:43:32.597221+00:00', '--job-id', '19', '--raw', '--subdir', 'DAGS_FOLDER/dev_data_ops.py', '--cfg-path', '/tmp/tmp4ydo_kgl']
[2022-11-18T08:43:37.142+0000] {standard_task_runner.py:83} INFO - Job 19: Subtask export_annotation
[2022-11-18T08:43:38.041+0000] {task_command.py:376} INFO - Running <TaskInstance: DevDataOps.export_annotation manual__2022-11-18T08:43:32.597221+00:00 [running]> on host d470c2e62263
[2022-11-18T08:43:38.521+0000] {taskinstance.py:1592} INFO - Exporting the following env vars:
AIRFLOW_CTX_DAG_OWNER=***
AIRFLOW_CTX_DAG_ID=DevDataOps
AIRFLOW_CTX_TASK_ID=export_annotation
AIRFLOW_CTX_EXECUTION_DATE=2022-11-18T08:43:32.597221+00:00
AIRFLOW_CTX_TRY_NUMBER=1
AIRFLOW_CTX_DAG_RUN_ID=manual__2022-11-18T08:43:32.597221+00:00
[2022-11-18T08:43:38.529+0000] {subprocess.py:63} INFO - Tmp dir root location: 
 /tmp
[2022-11-18T08:43:38.537+0000] {subprocess.py:75} INFO - Running command: ['/bin/bash', '-c', "curl         --request GET 'http://localhost:8081/api/projects/2/export?exportType=CSV' \\ \n        --header 'Authorization: Token 8823cc4fb910406253548fac3c458e495d6de86c' \\ \n        --output 'annotations.csv'"]
[2022-11-18T08:43:38.619+0000] {subprocess.py:86} INFO - Output:
[2022-11-18T08:43:38.647+0000] {subprocess.py:93} INFO -   % Total    % Received % Xferd  Average Speed   Time    Time     Time  Current
[2022-11-18T08:43:38.652+0000] {subprocess.py:93} INFO -                                  Dload  Upload   Total   Spent    Left  Speed
[2022-11-18T08:43:38.657+0000] {subprocess.py:93} INFO -   0     0    0     0    0     0      0      0 --:--:-- --:--:-- --:--:--     0  0     0    0     0    0     0      0      0 --:--:-- --:--:-- --:--:--     0
[2022-11-18T08:43:38.660+0000] {subprocess.py:93} INFO - curl: (7) Failed to connect to localhost port 8081: Connection refused
[2022-11-18T08:43:38.665+0000] {subprocess.py:93} INFO - curl: (3) URL using bad/illegal format or missing URL
[2022-11-18T08:43:38.674+0000] {subprocess.py:93} INFO - /bin/bash: line 2: --header: command not found
[2022-11-18T08:43:38.682+0000] {subprocess.py:93} INFO - /bin/bash: line 3: --output: command not found
[2022-11-18T08:43:38.686+0000] {subprocess.py:97} INFO - Command exited with return code 127
[2022-11-18T08:43:38.790+0000] {taskinstance.py:1851} ERROR - Task failed with exception
Traceback (most recent call last):
  File "/home/airflow/.local/lib/python3.7/site-packages/airflow/operators/bash.py", line 197, in execute
    f'Bash command failed. The command returned a non-zero exit code {result.exit_code}.'
airflow.exceptions.AirflowException: Bash command failed. The command returned a non-zero exit code 127.
[2022-11-18T08:43:38.806+0000] {taskinstance.py:1406} INFO - Marking task as FAILED. dag_id=DevDataOps, task_id=export_annotation, execution_date=20221118T084332, start_date=20221118T084336, end_date=20221118T084338
[2022-11-18T08:43:39.245+0000] {standard_task_runner.py:105} ERROR - Failed to execute job 19 for task export_annotation (Bash command failed. The command returned a non-zero exit code 127.; 2329)
[2022-11-18T08:43:39.440+0000] {local_task_job.py:159} INFO - Task exited with return code 1
[2022-11-18T08:43:39.515+0000] {taskinstance.py:2623} INFO - 0 downstream tasks scheduled from follow-on schedule check
